Workbook

Sheet Marginals
A1: POPULATION | I1: POPULATION
A2: Area | B2: Popn. | I2: Area | J2: Popn.
A3: A | B3: 80 | I3: A | J3: =B3/SUM($B$3:$B$5) -> 0.34188034
A4: B | B4: 70 | I4: B | J4: =B4/SUM($B$3:$B$5) -> 0.2991453
A5: C | B5: 84 | I5: C | J5: =B5/SUM($B$3:$B$5) -> 0.35897436
A6: Total | B6: =SUM(B3:B5) -> 234
A8: GENDER | I8: GENDER
A9: Area | B9: Female | C9: Male | D9: Total | I9: Area | J9: Female | K9: Male
A10: A | B10: 45 | C10: 34 | D10: =SUM(B10:C10) -> 79 | I10: A | J10: =B10/$D10 -> 0.56962025 | K10: =C10/$D10 -> 0.43037975
A11: B | B11: 40 | C11: 31 | D11: =SUM(B11:C11) -> 71 | I11: B | J11: =B11/$D11 -> 0.56338028 | K11: =C11/$D11 -> 0.43661972
A12: C | B12: 49 | C12: 35 | D12: =SUM(B12:C12) -> 84 | I12: C | J12: =B12/$D12 -> 0.58333333 | K12: =C12/$D12 -> 0.41666667
A13: Total | B13: =SUM(B10:B12) -> 134 | C13: =SUM(C10:C12) -> 100 | D13: =SUM(B13:C13) -> 234
A15: AGE | I15: AGE
A16: Area | B16: Young | C16: Adult | D16: Elderly | E16: Total | I16: Area | J16: Young | K16: Adult | L16: Elderly
A17: A | B17: 20 | C17: 31 | D17: 29 | E17: =SUM(B17:D17) -> 80 | I17: A | J17: =B17/$E17 -> 0.25 | K17: =C17/$E17 -> 0.3875 | L17: =D17/$E17 -> 0.3625
A18: B | B18: 25 | C18: 25 | D18: 20 | E18: =SUM(B18:D18) -> 70 | I18: B | J18: =B18/$E18 -> 0.35714286 | K18: =C18/$E18 -> 0.35714286 | L18: =D18/$E18 -> 0.28571429
A19: C | B19: 31 | C19: 34 | D19: 20 | E19: =SUM(B19:D19) -> 85 | I19: C | J19: =B19/$E19 -> 0.36470588 | K19: =C19/$E19 -> 0.4 | L19: =D19/$E19 -> 0.23529412
A20: Total | B20: =SUM(B17:B19) -> 76 | C20: =SUM(C17:C19) -> 90 | D20: =SUM(D17:D19) -> 69 | E20: =SUM(B20:D20) -> 235
A22: HEALTH | I22: HEALTH
A23: Area | B23: Good | C23: Fair | D23: Poor | E23: Total | I23: Area | J23: Good | K23: Fair | L23: Poor
A24: A | B24: 16 | C24: 30 | D24: 33 | E24: =SUM(B24:D24) -> 79 | I24: A | J24: =B24/$E24 -> 0.20253165 | K24: =C24/$E24 -> 0.37974684 | L24: =D24/$E24 -> 0.41772152
A25: B | B25: 14 | C25: 28 | D25: 29 | E25: =SUM(B25:D25) -> 71 | I25: B | J25: =B25/$E25 -> 0.1971831 | K25: =C25/$E25 -> 0.3943662 | L25: =D25/$E25 -> 0.4084507
A26: C | B26: 18 | C26: 33 | D26: 32 | E26: =SUM(B26:D26) -> 83 | I26: C | J26: =B26/$E26 -> 0.21686747 | K26: =C26/$E26 -> 0.39759036 | L26: =D26/$E26 -> 0.38554217
A27: Total | B27: =SUM(B24:B26) -> 48 | C27: =SUM(C24:C26) -> 91 | D27: =SUM(D24:D26) -> 94 | E27: =SUM(B27:D27) -> 233

Sheet Constraints
A1: GENDER x AGE | I1: GENDER x AGE
A2: Gender | B2: Age | E2: Total | I2: Gender | J2: Age | M2: Total
B3: Young | C3: Adult | D3: Elderly | J3: Young | K3: Adult | L3: Elderly
A4: Female | B4: 150 | C4: 250 | D4: 160 | E4: =SUM(B4:D4) -> 560 | I4: Female | J4: =B4/$E$6 -> 0.15 | K4: =C4/$E$6 -> 0.25 | L4: =D4/$E$6 -> 0.16 | M4: =SUM(J4:L4) -> 0.56
A5: Male | B5: 150 | C5: 170 | D5: 120 | E5: =SUM(B5:D5) -> 440 | I5: Male | J5: =B5/$E$6 -> 0.15 | K5: =C5/$E$6 -> 0.17 | L5: =D5/$E$6 -> 0.12 | M5: =SUM(J5:L5) -> 0.44
A6: Total | B6: =SUM(B4:B5) -> 300 | C6: =SUM(C4:C5) -> 420 | D6: =SUM(D4:D5) -> 280 | E6: =SUM(B6:D6) -> 1000 | I6: Total | J6: =SUM(J4:J5) -> 0.3 | K6: =SUM(K4:K5) -> 0.42 | L6: =SUM(L4:L5) -> 0.28 | M6: =SUM(J6:L6) -> 1
A8: GENDER x HEALTH | I8: GENDER x HEALTH
A9: Gender | B9: Health | E9: Total | I9: Gender | J9: Health | M9: Total
B10: Good | C10: Fair | D10: Poor | J10: Good | K10: Fair | L10: Poor
A11: Female | B11: 300 | C11: 160 | D11: 100 | E11: =SUM(B11:D11) -> 560 | I11: Female | J11: =B11/$E$13 -> 0.3 | K11: =C11/$E$13 -> 0.16 | L11: =D11/$E$13 -> 0.1 | M11: =SUM(J11:L11) -> 0.56
A12: Male | B12: 200 | C12: 140 | D12: 100 | E12: =SUM(B12:D12) -> 440 | I12: Gender | J12: =B12/$E$13 -> 0.2 | K12: =C12/$E$13 -> 0.14 | L12: =D12/$E$13 -> 0.1 | M12: =SUM(J12:L12) -> 0.44
A13: Total | B13: =SUM(B11:B12) -> 500 | C13: =SUM(C11:C12) -> 300 | D13: =SUM(D11:D12) -> 200 | E13: =SUM(B13:D13) -> 1000 | I13: Total | J13: =SUM(J11:J12) -> 0.5 | K13: =SUM(K11:K12) -> 0.3 | L13: =SUM(L11:L12) -> 0.2 | M13: =SUM(J13:L13) -> 1
A15: AGE x HEALTH | I15: AGE x HEALTH
A16: Age | B16: Health | E16: Total | I16: Age | J16: Health | M16: Total
B17: Good | C17: Fair | D17: Poor | J17: Good | K17: Fair | L17: Poor
A18: Young | B18: 180 | C18: 80 | D18: 40 | E18: =SUM(B18:D18) -> 300 | I18: Young | J18: =B18/$E$21 -> 0.18 | K18: =C18/$E$21 -> 0.08 | L18: =D18/$E$21 -> 0.04 | M18: =SUM(J18:L18) -> 0.3
A19: Adult | B19: 210 | C19: 130 | D19: 80 | E19: =SUM(B19:D19) -> 420 | I19: Adult | J19: =B19/$E$21 -> 0.21 | K19: =C19/$E$21 -> 0.13 | L19: =D19/$E$21 -> 0.08 | M19: =SUM(J19:L19) -> 0.42
A20: Elderly | B20: 110 | C20: 90 | D20: 80 | E20: =SUM(B20:D20) -> 280 | I20: Elderly | J20: =B20/$E$21 -> 0.11 | K20: =C20/$E$21 -> 0.09 | L20: =D20/$E$21 -> 0.08 | M20: =SUM(J20:L20) -> 0.28
A21: Total | B21: =SUM(B18:B20) -> 500 | C21: =SUM(C18:C20) -> 300 | D21: =SUM(D18:D20) -> 200 | E21: =SUM(B21:D21) -> 1000 | I21: Total | J21: =SUM(J18:J20) -> 0.5 | K21: =SUM(K18:K20) -> 0.3 | L21: =SUM(L18:L20) -> 0.2 | M21: =SUM(J21:L21) -> 1

Sheet National Fitting
A1: Assume independence
A3: So initial estimate for Area A, Female, Young, Good Health is given by
A5: PF(A),Y(A),G(A) = PF(A)*PY(A)*PG(A)
A7: PF(A) | B7: =Marginals!J10 -> 0.56962025
A8: PY(A) | B8: =Marginals!J17 -> 0.25
A9: PG(A) | B9: =Marginals!J24 -> 0.20253165
A11: PF(A),Y(A),G(A) | B11: =B7*B8*B9 -> 0.028841532
A13: SEED TABLE | H13: Iteration 1 | K13: Iteration 2 | N13: Iteration 3
A14: Gender | B14: Age | C14: Health | D14: P(G) | E14: P(A) | F14: P(H) | G14: P(G),(A),(H) | H14: Refactored (GxA) | I14: Refactored (GxH) | J14: Refactored (AxH) | K14: Refactored (GxA) | L14: Refactored (GxH) | M14: Refactored (AxH) | N14: Refactored (GxA) | O14: Refactored (GxH) | P14: Refactored (AxH)
A15: Female | B15: Young | C15: Good | D15: =Constraints!$M$4 -> 0.56 | E15: =Constraints!$M$18 -> 0.3 | F15: =Constraints!$J$13 -> 0.5 | G15: =D15*E15*F15 -> 0.084 | H15: =G15*$E$36 -> 0.075 | I15: =H15*$E$45 -> 0.080357143 | J15: =I15*E54 -> 0.097377049 | K15: =J15*$I$36 -> 0.09557607 | L15: =K15*$I$45 -> 0.096492882 | M15: =L15*I54 -> 0.096752575 | N15: =M15*$M$36 -> 0.096462388 | O15: =N15*$M$45 -> 0.09650633 | P15: =O15*M54 -> 0.096534795
A16: Female | B16: Young | C16: Fair | D16: =Constraints!$M$4 -> 0.56 | E16: =Constraints!$M$18 -> 0.3 | F16: =Constraints!$K$13 -> 0.3 | G16: =D16*E16*F16 -> 0.0504 | H16: =G16*$E$36 -> 0.045 | I16: =H16*$E$46 -> 0.042857143 | J16: =I16*E55 -> 0.037849462 | K16: =J16*$I$36 -> 0.03714944 | L16: =K16*$I$46 -> 0.036910703 | M16: =L16*I55 -> 0.036830086 | N16: =M16*$M$36 -> 0.036719622 | O16: =N16*$M$46 -> 0.036708421 | P16: =O16*M55 -> 0.036698784
A17: Female | B17: Young | C17: Poor | D17: =Constraints!$M$4 -> 0.56 | E17: =Constraints!$M$18 -> 0.3 | F17: =Constraints!$L$13 -> 0.2 | G17: =D17*E17*F17 -> 0.0336 | H17: =G17*$E$36 -> 0.03 | I17: =H17*$E$47 -> 0.026785714 | J17: =I17*E56 -> 0.0176 | K17: =J17*$I$36 -> 0.01727449 | L17: =K17*$I$47 -> 0.016966459 | M17: =L17*I56 -> 0.016868583 | N17: =M17*$M$36 -> 0.01681799 | O17: =N17*$M$47 -> 0.01680324 | P17: =O17*M56 -> 0.016791724
A18: Female | B18: Adult | C18: Good | D18: =Constraints!$M$4 -> 0.56 | E18: =Constraints!$M$19 -> 0.42 | F18: =Constraints!$J$13 -> 0.5 | G18: =D18*E18*F18 -> 0.1176 | H18: =G18*$E$37 -> 0.125 | I18: =H18*$E$45 -> 0.13392857 | J18: =I18*E57 -> 0.13316679 | K18: =J18*$I$37 -> 0.13315079 | L18: =K18*$I$45 -> 0.13442803 | M18: =L18*I57 -> 0.13430477 | N18: =M18*$M$37 -> 0.13431183 | O18: =N18*$M$45 -> 0.13437301 | P18: =O18*M57 -> 0.13436674
A19: Female | B19: Adult | C19: Fair | D19: =Constraints!$M$4 -> 0.56 | E19: =Constraints!$M$19 -> 0.42 | F19: =Constraints!$K$13 -> 0.3 | G19: =D19*E19*F19 -> 0.07056 | H19: =G19*$E$37 -> 0.075 | I19: =H19*$E$46 -> 0.071428571 | J19: =I19*E58 -> 0.073978272 | K19: =J19*$I$37 -> 0.073969379 | L19: =K19*$I$46 -> 0.073494022 | M19: =L19*I58 -> 0.073537793 | N19: =M19*$M$37 -> 0.073541658 | O19: =N19*$M$46 -> 0.073519224 | P19: =O19*M58 -> 0.073523039
A20: Female | B20: Adult | C20: Poor | D20: =Constraints!$M$4 -> 0.56 | E20: =Constraints!$M$19 -> 0.42 | F20: =Constraints!$L$13 -> 0.2 | G20: =D20*E20*F20 -> 0.04704 | H20: =G20*$E$37 -> 0.05 | I20: =H20*$E$47 -> 0.044642857 | J20: =I20*E59 -> 0.04288499 | K20: =J20*$I$37 -> 0.042879835 | L20: =K20*$I$47 -> 0.042115221 | M20: =L20*I59 -> 0.0421443 | N20: =M20*$M$37 -> 0.042146515 | O20: =N20*$M$47 -> 0.042109552 | P20: =O20*M59 -> 0.042109649
A21: Female | B21: Elderly | C21: Good | D21: =Constraints!$M$4 -> 0.56 | E21: =Constraints!$M$20 -> 0.28 | F21: =Constraints!$J$13 -> 0.5 | G21: =D21*E21*F21 -> 0.0784 | H21: =G21*$E$38 -> 0.08 | I21: =H21*$E$45 -> 0.085714286 | J21: =I21*E60 -> 0.067222222 | K21: =J21*$I$38 -> 0.068422741 | L21: =K21*$I$45 -> 0.069079085 | M21: =L21*I60 -> 0.068897196 | N21: =M21*$M$38 -> 0.069089185 | O21: =N21*$M$45 -> 0.069120658 | P21: =O21*M60 -> 0.069093474
A22: Female | B22: Elderly | C22: Fair | D22: =Constraints!$M$4 -> 0.56 | E22: =Constraints!$M$20 -> 0.28 | F22: =Constraints!$K$13 -> 0.3 | G22: =D22*E22*F22 -> 0.04704 | H22: =G22*$E$38 -> 0.048 | I22: =H22*$E$46 -> 0.045714286 | J22: =I22*E61 -> 0.049040248 | K22: =J22*$I$38 -> 0.049916055 | L22: =K22*$I$46 -> 0.049595275 | M22: =L22*I61 -> 0.049649191 | N22: =M22*$M$38 -> 0.049787543 | O22: =N22*$M$46 -> 0.049772355 | P22: =O22*M61 -> 0.049780244
A23: Female | B23: Elderly | C23: Poor | D23: =Constraints!$M$4 -> 0.56 | E23: =Constraints!$M$20 -> 0.28 | F23: =Constraints!$L$13 -> 0.2 | G23: =D23*E23*F23 -> 0.03136 | H23: =G23*$E$38 -> 0.032 | I23: =H23*$E$47 -> 0.028571429 | J23: =I23*E62 -> 0.040930233 | K23: =J23*$I$38 -> 0.041661204 | L23: =K23*$I$47 -> 0.04091832 | M23: =L23*I62 -> 0.041008997 | N23: =M23*$M$38 -> 0.041123273 | O23: =N23*$M$47 -> 0.041087207 | P23: =O23*M62 -> 0.041101207
A24: Male | B24: Young | C24: Good | D24: =Constraints!$M$5 -> 0.44 | E24: =Constraints!$M$18 -> 0.3 | F24: =Constraints!$J$13 -> 0.5 | G24: =D24*E24*F24 -> 0.066 | H24: =G24*$E$39 -> 0.075 | I24: =H24*$E$48 -> 0.068181818 | J24: =I24*E54 -> 0.082622951 | K24: =J24*$I$39 -> 0.08420975 | L24: =K24*$I$48 -> 0.083023982 | M24: =L24*I54 -> 0.083247425 | N24: =M24*$M$39 -> 0.083498613 | O24: =N24*$M$48 -> 0.083440593 | P24: =O24*M54 -> 0.083465205
A25: Male | B25: Young | C25: Fair | D25: =Constraints!$M$5 -> 0.44 | E25: =Constraints!$M$18 -> 0.3 | F25: =Constraints!$K$13 -> 0.3 | G25: =D25*E25*F25 -> 0.0396 | H25: =G25*$E$39 -> 0.045 | I25: =H25*$E$49 -> 0.047727273 | J25: =I25*E55 -> 0.042150538 | K25: =J25*$I$39 -> 0.042960052 | L25: =K25*$I$49 -> 0.043264409 | M25: =L25*I55 -> 0.043169914 | N25: =M25*$M$39 -> 0.043300174 | O25: =N25*$M$49 -> 0.043312588 | P25: =O25*M55 -> 0.043301216
A26: Male | B26: Young | C26: Poor | D26: =Constraints!$M$5 -> 0.44 | E26: =Constraints!$M$18 -> 0.3 | F26: =Constraints!$L$13 -> 0.2 | G26: =D26*E26*F26 -> 0.0264 | H26: =G26*$E$39 -> 0.03 | I26: =H26*$E$50 -> 0.034090909 | J26: =I26*E56 -> 0.0224 | K26: =J26*$I$39 -> 0.022830199 | L26: =K26*$I$50 -> 0.023265632 | M26: =L26*I56 -> 0.023131417 | N26: =M26*$M$39 -> 0.023201213 | O26: =N26*$M$50 -> 0.023224192 | P26: =O26*M56 -> 0.023208276
A27: Male | B27: Adult | C27: Good | D27: =Constraints!$M$5 -> 0.44 | E27: =Constraints!$M$19 -> 0.42 | F27: =Constraints!$J$13 -> 0.5 | G27: =D27*E27*F27 -> 0.0924 | H27: =G27*$E$40 -> 0.085 | I27: =H27*$E$48 -> 0.077272727 | J27: =I27*E57 -> 0.076833205 | K27: =J27*$I$40 -> 0.076846792 | L27: =K27*$I$48 -> 0.075764703 | M27: =L27*I57 -> 0.075695231 | N27: =M27*$M$40 -> 0.075689381 | O27: =N27*$M$48 -> 0.075636788 | P27: =O27*M57 -> 0.075633258
A28: Male | B28: Adult | C28: Fair | D28: =Constraints!$M$5 -> 0.44 | E28: =Constraints!$M$19 -> 0.42 | F28: =Constraints!$K$13 -> 0.3 | G28: =D28*E28*F28 -> 0.05544 | H28: =G28*$E$40 -> 0.051 | I28: =H28*$E$49 -> 0.054090909 | J28: =I28*E58 -> 0.056021728 | K28: =J28*$I$40 -> 0.056031635 | L28: =K28*$I$49 -> 0.0564286 | M28: =L28*I58 -> 0.056462207 | N28: =M28*$M$40 -> 0.056457844 | O28: =N28*$M$49 -> 0.05647403 | P28: =O28*M58 -> 0.056476961
A29: Male | B29: Adult | C29: Poor | D29: =Constraints!$M$5 -> 0.44 | E29: =Constraints!$M$19 -> 0.42 | F29: =Constraints!$L$13 -> 0.2 | G29: =D29*E29*F29 -> 0.03696 | H29: =G29*$E$40 -> 0.034 | I29: =H29*$E$50 -> 0.038636364 | J29: =I29*E59 -> 0.03711501 | K29: =J29*$I$40 -> 0.037121573 | L29: =K29*$I$50 -> 0.037829581 | M29: =L29*I59 -> 0.0378557 | N29: =M29*$M$40 -> 0.037852775 | O29: =N29*$M$50 -> 0.037890265 | P29: =O29*M59 -> 0.037890351
A30: Male | B30: Elderly | C30: Good | D30: =Constraints!$M$5 -> 0.44 | E30: =Constraints!$M$20 -> 0.28 | F30: =Constraints!$J$13 -> 0.5 | G30: =D30*E30*F30 -> 0.0616 | H30: =G30*$E$41 -> 0.06 | I30: =H30*$E$48 -> 0.054545455 | J30: =I30*E60 -> 0.042777778 | K30: =J30*$I$41 -> 0.041799905 | L30: =K30*$I$48 -> 0.041211315 | M30: =L30*I60 -> 0.041102804 | N30: =M30*$M$41 -> 0.040951075 | O30: =N30*$M$48 -> 0.040922619 | P30: =O30*M60 -> 0.040906526
A31: Male | B31: Elderly | C31: Fair | D31: =Constraints!$M$5 -> 0.44 | E31: =Constraints!$M$20 -> 0.28 | F31: =Constraints!$K$13 -> 0.3 | G31: =D31*E31*F31 -> 0.03696 | H31: =G31*$E$41 -> 0.036 | I31: =H31*$E$49 -> 0.038181818 | J31: =I31*E61 -> 0.040959752 | K31: =J31*$I$41 -> 0.040023438 | L31: =K31*$I$49 -> 0.040306991 | M31: =L31*I61 -> 0.040350809 | N31: =M31*$M$41 -> 0.040201856 | O31: =N31*$M$49 -> 0.040213382 | P31: =O31*M61 -> 0.040219756
A32: Male | B32: Elderly | C32: Poor | D32: =Constraints!$M$5 -> 0.44 | E32: =Constraints!$M$20 -> 0.28 | F32: =Constraints!$L$13 -> 0.2 | G32: =D32*E32*F32 -> 0.02464 | H32: =G32*$E$41 -> 0.024 | I32: =H32*$E$50 -> 0.027272727 | J32: =I32*E62 -> 0.039069767 | K32: =J32*$I$41 -> 0.038176657 | L32: =K32*$I$50 -> 0.038904788 | M32: =L32*I62 -> 0.038991003 | N32: =M32*$M$41 -> 0.038847069 | O32: =N32*$M$50 -> 0.038885544 | P32: =O32*M62 -> 0.038898793
A34: GENDER x AGE
A35: Gender | B35: Age | C35: Sum(P) | D35: Original | E35: Factor | F35: Iteration 1 | G35: AbsDiff | H35: Sum(P) | I35: Factor | J35: Iteration 2 | K35: AbsDiff | L35: Sum(P) | M35: Factor | N35: Iteration 2 | O35: AbsDiff
A36: Female | B36: Young | C36: =SUMIFS($G$15:$G$32,$A$15:$A$32,$A36,$B$15:$B$32,$B36) -> 0.168 | D36: =Constraints!$J$4 -> 0.15 | E36: =D36/C36 -> 0.89285714 | F36: =SUMIFS($J$15:$J$32,$A$15:$A$32,$A36,$B$15:$B$32,$B36) -> 0.15282651 | G36: =ABS($D36-F36) -> 0.0028265115 | H36: =SUMIFS($J$15:$J$32,$A$15:$A$32,$A36,$B$15:$B$32,$B36) -> 0.15282651 | I36: =$D36/H36 -> 0.9815051 | J36: =SUMIFS($M$15:$M$32,$A$15:$A$32,$A36,$B$15:$B$32,$B36) -> 0.15045124 | K36: =ABS($D36-J36) -> 0.00045124314 | L36: =SUMIFS($M$15:$M$32,$A$15:$A$32,$A36,$B$15:$B$32,$B36) -> 0.15045124 | M36: =$D36/L36 -> 0.99700074 | N36: =SUMIFS($P$15:$P$32,$A$15:$A$32,$A36,$B$15:$B$32,$B36) -> 0.1500253 | O36: =ABS($D36-N36) -> 2.530359e-05
A37: Female | B37: Adult | C37: =SUMIFS($G$15:$G$32,$A$15:$A$32,$A37,$B$15:$B$32,$B37) -> 0.2352 | D37: =Constraints!$K$4 -> 0.25 | E37: =D37/C37 -> 1.0629252 | F37: =SUMIFS($J$15:$J$32,$A$15:$A$32,$A37,$B$15:$B$32,$B37) -> 0.25003006 | G37: =ABS($D37-F37) -> 3.0057143e-05 | H37: =SUMIFS($J$15:$J$32,$A$15:$A$32,$A37,$B$15:$B$32,$B37) -> 0.25003006 | I37: =$D37/H37 -> 0.99987979 | J37: =SUMIFS($M$15:$M$32,$A$15:$A$32,$A37,$B$15:$B$32,$B37) -> 0.24998686 | K37: =ABS($D37-J37) -> 1.313804e-05 | L37: =SUMIFS($M$15:$M$32,$A$15:$A$32,$A37,$B$15:$B$32,$B37) -> 0.24998686 | M37: =$D37/L37 -> 1.0000526 | N37: =SUMIFS($P$15:$P$32,$A$15:$A$32,$A37,$B$15:$B$32,$B37) -> 0.24999943 | O37: =ABS($D37-N37) -> 5.704289e-07
A38: Female | B38: Elderly | C38: =SUMIFS($G$15:$G$32,$A$15:$A$32,$A38,$B$15:$B$32,$B38) -> 0.1568 | D38: =Constraints!$L$4 -> 0.16 | E38: =D38/C38 -> 1.0204082 | F38: =SUMIFS($J$15:$J$32,$A$15:$A$32,$A38,$B$15:$B$32,$B38) -> 0.1571927 | G38: =ABS($D38-F38) -> 0.0028072975 | H38: =SUMIFS($J$15:$J$32,$A$15:$A$32,$A38,$B$15:$B$32,$B38) -> 0.1571927 | I38: =$D38/H38 -> 1.017859 | J38: =SUMIFS($M$15:$M$32,$A$15:$A$32,$A38,$B$15:$B$32,$B38) -> 0.15955538 | K38: =ABS($D38-J38) -> 0.0004446158 | L38: =SUMIFS($M$15:$M$32,$A$15:$A$32,$A38,$B$15:$B$32,$B38) -> 0.15955538 | M38: =$D38/L38 -> 1.0027866 | N38: =SUMIFS($P$15:$P$32,$A$15:$A$32,$A38,$B$15:$B$32,$B38) -> 0.15997493 | O38: =ABS($D38-N38) -> 2.5074454e-05
A39: Male | B39: Young | C39: =SUMIFS($G$15:$G$32,$A$15:$A$32,$A39,$B$15:$B$32,$B39) -> 0.132 | D39: =Constraints!$J$5 -> 0.15 | E39: =D39/C39 -> 1.1363636 | F39: =SUMIFS($J$15:$J$32,$A$15:$A$32,$A39,$B$15:$B$32,$B39) -> 0.14717349 | G39: =ABS($D39-F39) -> 0.0028265115 | H39: =SUMIFS($J$15:$J$32,$A$15:$A$32,$A39,$B$15:$B$32,$B39) -> 0.14717349 | I39: =$D39/H39 -> 1.0192053 | J39: =SUMIFS($M$15:$M$32,$A$15:$A$32,$A39,$B$15:$B$32,$B39) -> 0.14954876 | K39: =ABS($D39-J39) -> 0.00045124314 | L39: =SUMIFS($M$15:$M$32,$A$15:$A$32,$A39,$B$15:$B$32,$B39) -> 0.14954876 | M39: =$D39/L39 -> 1.0030174 | N39: =SUMIFS($P$15:$P$32,$A$15:$A$32,$A39,$B$15:$B$32,$B39) -> 0.1499747 | O39: =ABS($D39-N39) -> 2.530359e-05
A40: Male | B40: Adult | C40: =SUMIFS($G$15:$G$32,$A$15:$A$32,$A40,$B$15:$B$32,$B40) -> 0.1848 | D40: =Constraints!$K$5 -> 0.17 | E40: =D40/C40 -> 0.91991342 | F40: =SUMIFS($J$15:$J$32,$A$15:$A$32,$A40,$B$15:$B$32,$B40) -> 0.16996994 | G40: =ABS($D40-F40) -> 3.0057143e-05 | H40: =SUMIFS($J$15:$J$32,$A$15:$A$32,$A40,$B$15:$B$32,$B40) -> 0.16996994 | I40: =$D40/H40 -> 1.0001768 | J40: =SUMIFS($M$15:$M$32,$A$15:$A$32,$A40,$B$15:$B$32,$B40) -> 0.17001314 | K40: =ABS($D40-J40) -> 1.313804e-05 | L40: =SUMIFS($M$15:$M$32,$A$15:$A$32,$A40,$B$15:$B$32,$B40) -> 0.17001314 | M40: =$D40/L40 -> 0.99992272 | N40: =SUMIFS($P$15:$P$32,$A$15:$A$32,$A40,$B$15:$B$32,$B40) -> 0.17000057 | O40: =ABS($D40-N40) -> 5.704289e-07
A41: Male | B41: Elderly | C41: =SUMIFS($G$15:$G$32,$A$15:$A$32,$A41,$B$15:$B$32,$B41) -> 0.1232 | D41: =Constraints!$L$5 -> 0.12 | E41: =D41/C41 -> 0.97402597 | F41: =SUMIFS($J$15:$J$32,$A$15:$A$32,$A41,$B$15:$B$32,$B41) -> 0.1228073 | G41: =ABS($D41-F41) -> 0.0028072975 | H41: =SUMIFS($J$15:$J$32,$A$15:$A$32,$A41,$B$15:$B$32,$B41) -> 0.1228073 | I41: =$D41/H41 -> 0.97714063 | J41: =SUMIFS($M$15:$M$32,$A$15:$A$32,$A41,$B$15:$B$32,$B41) -> 0.12044462 | K41: =ABS($D41-J41) -> 0.0004446158 | L41: =SUMIFS($M$15:$M$32,$A$15:$A$32,$A41,$B$15:$B$32,$B41) -> 0.12044462 | M41: =$D41/L41 -> 0.99630855 | N41: =SUMIFS($P$15:$P$32,$A$15:$A$32,$A41,$B$15:$B$32,$B41) -> 0.12002507 | O41: =ABS($D41-N41) -> 2.5074454e-05
F42: MaxAD | G42: =MAX(G36:G41) -> 0.0028265115 | J42: MaxAD | K42: =MAX(K36:K41) -> 0.00045124314 | N42: MaxAD | O42: =MAX(O36:O41) -> 2.530359e-05
A43: GENDER x HEALTH
A44: Gender | B44: Health | C44: Sum(P) | D44: Original | E44: Factor | F44: Iteration 1 | G44: AbsDiff | H44: Sum(P) | I44: Factor | J44: Iteration 2 | K44: AbsDiff | L44: Sum(P) | M44: Factor | N44: Iteration 3 | O44: AbsDiff
A45: Female | B45: Good | C45: =SUMIFS($H$15:$H$32,$A$15:$A$32,$A45,$C$15:$C$32,$B45) -> 0.28 | D45: =Constraints!$J$11 -> 0.3 | E45: =D45/C45 -> 1.0714286 | F45: =SUMIFS($J$15:$J$32,$A$15:$A$32,$A45,$C$15:$C$32,$B45) -> 0.29776607 | G45: =ABS($D45-F45) -> 0.0022339338 | H45: =SUMIFS($K$15:$K$32,$A$15:$A$32,$A45,$C$15:$C$32,$B45) -> 0.2971496 | I45: =$D45/H45 -> 1.0095925 | J45: =SUMIFS($M$15:$M$32,$A$15:$A$32,$A45,$C$15:$C$32,$B45) -> 0.29995454 | K45: =ABS($D45-J45) -> 4.5459744e-05 | L45: =SUMIFS($N$15:$N$32,$A$15:$A$32,$A45,$C$15:$C$32,$B45) -> 0.2998634 | M45: =$D45/L45 -> 1.0004555 | N45: =SUMIFS($P$15:$P$32,$A$15:$A$32,$A45,$C$15:$C$32,$B45) -> 0.29999501 | O45: =ABS($D45-N45) -> 4.9882104e-06
A46: Female | B46: Fair | C46: =SUMIFS($H$15:$H$32,$A$15:$A$32,$A46,$C$15:$C$32,$B46) -> 0.168 | D46: =Constraints!$K$11 -> 0.16 | E46: =D46/C46 -> 0.95238095 | F46: =SUMIFS($J$15:$J$32,$A$15:$A$32,$A46,$C$15:$C$32,$B46) -> 0.16086798 | G46: =ABS($D46-F46) -> 0.00086798216 | H46: =SUMIFS($K$15:$K$32,$A$15:$A$32,$A46,$C$15:$C$32,$B46) -> 0.16103487 | I46: =$D46/H46 -> 0.9935736 | J46: =SUMIFS($M$15:$M$32,$A$15:$A$32,$A46,$C$15:$C$32,$B46) -> 0.16001707 | K46: =ABS($D46-J46) -> 1.7069178e-05 | L46: =SUMIFS($N$15:$N$32,$A$15:$A$32,$A46,$C$15:$C$32,$B46) -> 0.16004882 | M46: =$D46/L46 -> 0.99969495 | N46: =SUMIFS($P$15:$P$32,$A$15:$A$32,$A46,$C$15:$C$32,$B46) -> 0.16000207 | O46: =ABS($D46-N46) -> 2.0667779e-06
...

Sheet Local Fitting A
A1: SEED TABLE | E1: Iteration 1 | H1: Iteration 2 | K1: Iteration 3 | N1: Iteration 4
A2: Gender | B2: Age | C2: Health | D2: P(G),(A),(H) | E2: Refactored P(G) | F2: Refactored P(A) | G2: Refactored P(H) | H2: Refactored P(G) | I2: Refactored P(A) | J2: Refactored P(H) | K2: Refactored P(G) | L2: Refactored P(A) | M2: Refactored P(H) | N2: Refactored P(G) | O2: Refactored P(A) | P2: Refactored P(H)
A3: Female | B3: Young | C3: Good | D3: ='National Fitting'!P15 -> 0.096534795 | E3: =D3*$D$23 -> 0.098193229 | F3: =E3*$D$28 -> 0.082019565 | G3: =F3*$D$34 -> 0.03410816 | H3: =G3*$H$23 -> 0.035563653 | I3: =H3*$H$28 -> 0.042208741 | J3: =I3*$H$34 -> 0.040630794 | K3: =J3*$L$23 -> 0.040886508 | L3: =K3*$L$28 -> 0.041156034 | M3: =L3*$L$34 -> 0.041066151 | N3: =M3*$P$23 -> 0.041078065 | O3: =N3*$P$28 -> 0.04109255 | P3: =O3*$P$34 -> 0.041087999
A4: Female | B4: Young | C4: Fair | D4: ='National Fitting'!P16 -> 0.036698784 | E4: =D4*$D$23 -> 0.037329256 | F4: =E4*$D$28 -> 0.031180656 | G4: =F4*$D$35 -> 0.039104798 | H4: =G4*$H$23 -> 0.040773512 | I4: =H4*$H$28 -> 0.048392065 | J4: =I4*$H$35 -> 0.048152138 | K4: =J4*$L$23 -> 0.048455188 | L4: =K4*$L$28 -> 0.048774608 | M4: =L4*$L$35 -> 0.048764826 | N4: =M4*$P$23 -> 0.048778973 | O4: =N4*$P$28 -> 0.048796174 | P4: =O4*$P$35 -> 0.048795644
A5: Female | B5: Young | C5: Poor | D5: ='National Fitting'!P17 -> 0.016791724 | E5: =D5*$D$23 -> 0.0170802 | F5: =E5*$D$28 -> 0.014266876 | G5: =F5*$D$36 -> 0.028354838 | H5: =G5*$H$23 -> 0.02956482 | I5: =H5*$H$28 -> 0.035089023 | J5: =I5*$H$36 -> 0.035928286 | K5: =J5*$L$23 -> 0.036154405 | L5: =K5*$L$28 -> 0.036392737 | M5: =L5*$L$36 -> 0.03643805 | N5: =M5*$P$23 -> 0.036448621 | O5: =N5*$P$28 -> 0.036461474 | P5: =O5*$P$36 -> 0.036463792
A6: Female | B6: Adult | C6: Good | D6: ='National Fitting'!P18 -> 0.13436674 | E6: =D6*$D$23 -> 0.13667511 | F6: =E6*$D$29 -> 0.12592581 | G6: =F6*$D$34 -> 0.052366746 | H6: =G6*$H$23 -> 0.054601386 | I6: =H6*$H$29 -> 0.05592857 | J6: =I6*$H$34 -> 0.053837716 | K6: =J6*$L$23 -> 0.05417655 | L6: =K6*$L$29 -> 0.054194285 | M6: =L6*$L$34 -> 0.054075927 | N6: =M6*$P$23 -> 0.054091615 | O6: =N6*$P$29 -> 0.054092652 | P6: =O6*$P$34 -> 0.05408666
A7: Female | B7: Adult | C7: Fair | D7: ='National Fitting'!P19 -> 0.073523039 | E7: =D7*$D$23 -> 0.074786139 | F7: =E7*$D$29 -> 0.068904316 | G7: =F7*$D$35 -> 0.086415417 | H7: =G7*$H$23 -> 0.090103011 | I7: =H7*$H$29 -> 0.092293126 | J7: =I7*$H$35 -> 0.091835537 | K7: =J7*$L$23 -> 0.092413514 | L7: =K7*$L$29 -> 0.092443766 | M7: =L7*$L$35 -> 0.092425227 | N7: =M7*$P$23 -> 0.092452041 | O7: =N7*$P$29 -> 0.092453813 | P7: =O7*$P$35 -> 0.092452809
A8: Female | B8: Adult | C8: Poor | D8: ='National Fitting'!P20 -> 0.042109649 | E8: =D8*$D$23 -> 0.042833077 | F8: =E8*$D$29 -> 0.039464317 | G8: =F8*$D$36 -> 0.078433733 | H8: =G8*$H$23 -> 0.081780725 | I8: =H8*$H$29 -> 0.083768552 | J8: =I8*$H$36 -> 0.085772139 | K8: =J8*$L$23 -> 0.086311955 | L8: =K8*$L$29 -> 0.08634021 | M8: =L8*$L$36 -> 0.086447713 | N8: =M8*$P$23 -> 0.086472792 | O8: =N8*$P$29 -> 0.08647445 | P8: =O8*$P$36 -> 0.086479949
A9: Female | B9: Elderly | C9: Good | D9: ='National Fitting'!P21 -> 0.069093474 | E9: =D9*$D$23 -> 0.070280476 | F9: =E9*$D$30 -> 0.09094785 | G9: =F9*$D$34 -> 0.037821022 | H9: =G9*$H$23 -> 0.039434954 | I9: =H9*$H$30 -> 0.03477688 | J9: =I9*$H$34 -> 0.033476769 | K9: =J9*$L$23 -> 0.033687458 | L9: =K9*$L$30 -> 0.033524319 | M9: =L9*$L$34 -> 0.033451103 | N9: =M9*$P$23 -> 0.033460808 | O9: =N9*$P$30 -> 0.03345199 | P9: =O9*$P$34 -> 0.033448284
A10: Female | B10: Elderly | C10: Fair | D10: ='National Fitting'!P22 -> 0.049780244 | E10: =D10*$D$23 -> 0.050635451 | F10: =E10*$D$30 -> 0.065525814 | G10: =F10*$D$35 -> 0.082178314 | H10: =G10*$H$23 -> 0.085685098 | I10: =H10*$H$30 -> 0.075563938 | J10: =I10*$H$35 -> 0.075189293 | K10: =J10*$L$23 -> 0.075662504 | L10: =K10*$L$30 -> 0.075296091 | M10: =L10*$L$35 -> 0.075280991 | N10: =M10*$P$23 -> 0.075302831 | O10: =N10*$P$30 -> 0.075282986 | P10: =O10*$P$35 -> 0.075282169
A11: Female | B11: Elderly | C11: Poor | D11: ='National Fitting'!P23 -> 0.041101207 | E11: =D11*$D$23 -> 0.041807311 | F11: =E11*$D$30 -> 0.054101584 | G11: =F11*$D$36 -> 0.10752471 | H11: =G11*$H$23 -> 0.11211309 | I11: =H11*$H$30 -> 0.098870248 | J11: =I11*$H$36 -> 0.10123504 | K11: =J11*$L$23 -> 0.10187217 | L11: =K11*$L$30 -> 0.10137883 | M11: =L11*$L$36 -> 0.10150506 | N11: =M11*$P$23 -> 0.10153451 | O11: =N11*$P$30 -> 0.10150775 | P11: =O11*$P$36 -> 0.1015142
A12: Male | B12: Young | C12: Good | D12: ='National Fitting'!P24 -> 0.083465205 | E12: =D12*$D$24 -> 0.08164024 | F12: =E12*$D$28 -> 0.068193062 | G12: =F12*$D$34 -> 0.028358354 | H12: =G12*$H$24 -> 0.026901189 | I12: =H12*$H$28 -> 0.03192769 | J12: =I12*$H$34 -> 0.030734094 | K12: =J12*$L$24 -> 0.030481776 | L12: =K12*$L$28 -> 0.030682714 | M12: =L12*$L$34 -> 0.030615704 | N12: =M12*$P$24 -> 0.030603956 | O12: =N12*$P$28 -> 0.030614748 | P12: =O12*$P$34 -> 0.030611357
A13: Male | B13: Young | C13: Fair | D13: ='National Fitting'!P25 -> 0.043301216 | E13: =D13*$D$24 -> 0.042354437 | F13: =E13*$D$28 -> 0.035378126 | G13: =F13*$D$35 -> 0.044368999 | H13: =G13*$H$24 -> 0.042089143 | I13: =H13*$H$28 -> 0.049953522 | J13: =I13*$H$35 -> 0.049705853 | K13: =J13*$L$24 -> 0.049297782 | L13: =K13*$L$28 -> 0.049622756 | M13: =L13*$L$35 -> 0.049612804 | N13: =M13*$P$24 -> 0.049593767 | O13: =N13*$P$28 -> 0.049611256 | P13: =O13*$P$35 -> 0.049610717
A14: Male | B14: Young | C14: Poor | D14: ='National Fitting'!P26 -> 0.023208276 | E14: =D14*$D$24 -> 0.022700827 | F14: =E14*$D$28 -> 0.018961715 | G14: =F14*$D$36 -> 0.03768564 | H14: =G14*$H$24 -> 0.035749201 | I14: =H14*$H$28 -> 0.042428959 | J14: =I14*$H$36 -> 0.04344378 | K14: =J14*$L$24 -> 0.043087119 | L14: =K14*$L$28 -> 0.043371152 | M14: =L14*$L$36 -> 0.043425154 | N14: =M14*$P$24 -> 0.043408491 | O14: =N14*$P$28 -> 0.043423798 | P14: =O14*$P$36 -> 0.043426559
A15: Male | B15: Adult | C15: Good | D15: ='National Fitting'!P27 -> 0.075633258 | E15: =D15*$D$24 -> 0.073979539 | F15: =E15*$D$29 -> 0.068161155 | G15: =F15*$D$34 -> 0.028345085 | H15: =G15*$H$24 -> 0.026888602 | I15: =H15*$H$29 -> 0.027542177 | J15: =I15*$H$34 -> 0.026512531 | K15: =J15*$L$24 -> 0.02629487 | L15: =K15*$L$29 -> 0.026303478 | M15: =L15*$L$34 -> 0.026246033 | N15: =M15*$P$24 -> 0.026235962 | O15: =N15*$P$29 -> 0.026236464 | P15: =O15*$P$34 -> 0.026233558
A16: Male | B16: Adult | C16: Fair | D16: ='National Fitting'!P28 -> 0.056476961 | E16: =D16*$D$24 -> 0.055242094 | F16: =E16*$D$29 -> 0.050897383 | G16: =F16*$D$35 -> 0.063832264 | H16: =G16*$H$24 -> 0.060552308 | I16: =H16*$H$29 -> 0.062024141 | J16: =I16*$H$35 -> 0.061716625 | K16: =J16*$L$24 -> 0.06120995 | L16: =K16*$L$29 -> 0.061229987 | M16: =L16*$L$35 -> 0.061217708 | N16: =M16*$P$24 -> 0.061194218 | O16: =N16*$P$29 -> 0.061195391 | P16: =O16*$P$35 -> 0.061194726
A17: Male | B17: Adult | C17: Poor | D17: ='National Fitting'!P29 -> 0.037890351 | E17: =D17*$D$24 -> 0.03706188 | F17: =E17*$D$29 -> 0.034147016 | G17: =F17*$D$36 -> 0.067865812 | H17: =G17*$H$24 -> 0.064378596 | I17: =H17*$H$29 -> 0.065943433 | J17: =I17*$H$36 -> 0.067520676 | K17: =J17*$L$24 -> 0.066966351 | L17: =K17*$L$29 -> 0.066988273 | M17: =L17*$L$36 -> 0.067071681 | N17: =M17*$P$24 -> 0.067045944 | O17: =N17*$P$29 -> 0.06704723 | P17: =O17*$P$36 -> 0.067051493
A18: Male | B18: Elderly | C18: Good | D18: ='National Fitting'!P30 -> 0.040906526 | E18: =D18*$D$24 -> 0.040012106 | F18: =E18*$D$30 -> 0.051778462 | G18: =F18*$D$34 -> 0.021532278 | H18: =G18*$H$24 -> 0.020425864 | I18: =H18*$H$30 -> 0.018013152 | J18: =I18*$H$34 -> 0.017339742 | K18: =J18*$L$24 -> 0.017197387 | L18: =K18*$L$30 -> 0.017114105 | M18: =L18*$L$34 -> 0.017076729 | N18: =M18*$P$24 -> 0.017070176 | O18: =N18*$P$30 -> 0.017065677 | P18: =O18*$P$34 -> 0.017063787
A19: Male | B19: Elderly | C19: Fair | D19: ='National Fitting'!P31 -> 0.040219756 | E19: =D19*$D$24 -> 0.039340352 | F19: =E19*$D$30 -> 0.050909166 | G19: =F19*$D$35 -> 0.063847043 | H19: =G19*$H$24 -> 0.060566327 | I19: =H19*$H$30 -> 0.053412207 | J19: =I19*$H$35 -> 0.053147389 | K19: =J19*$L$24 -> 0.052711065 | L19: =K19*$L$30 -> 0.052455799 | M19: =L19*$L$35 -> 0.052445279 | N19: =M19*$P$24 -> 0.052425155 | O19: =N19*$P$30 -> 0.05241134 | P19: =O19*$P$35 -> 0.05241077
A20: Male | B20: Elderly | C20: Poor | D20: ='National Fitting'!P32 -> 0.038898793 | E20: =D20*$D$24 -> 0.038048272 | F20: =E20*$D$30 -> 0.049237124 | G20: =F20*$D$36 -> 0.097856791 | H20: =G20*$H$24 -> 0.092828518 | I20: =H20*$H$30 -> 0.081863575 | J20: =I20*$H$36 -> 0.083821598 | K20: =J20*$L$24 -> 0.083133447 | L20: =K20*$L$30 -> 0.082730854 | M20: =L20*$L$36 -> 0.082833862 | N20: =M20*$P$24 -> 0.082802078 | O20: =N20*$P$30 -> 0.082780257 | P20: =O20*$P$36 -> 0.082785521
A22: GENDER | B22: Start | C22: Sum(P) | D22: Factor | E22: Iteration 1 | F22: AbsDiff | G22: Sum(P) | H22: Factor | I22: Iteration 2 | J22: AbsDiff | K22: Sum(P) | L22: Factor | M22: Iteration 3 | N22: AbsDiff | O22: Sum(P) | P22: Factor | Q22: Iteration 4 | R22: AbsDiff
A23: Female | B23: =Marginals!$J$10 -> 0.56962025 | C23: =SUMIF($A$3:$A$20,$A23,$D$3:$D$20) -> 0.55999966 | D23: =$B23/C23 -> 1.0171796 | E23: =SUMIF($A$3:$A$20,$A23,$G$3:$G$20) -> 0.54630773 | F23: =ABS($B23-E23) -> 0.023312519 | G23: =SUMIF($A$3:$A$20,$A23,$G$3:$G$20) -> 0.54630773 | H23: =$B23/G23 -> 1.0426729 | I23: =SUMIF($A$3:$A$20,$A23,$J$3:$J$20) -> 0.56605771 | J23: =ABS($B23-I23) -> 0.0035625412 | K23: =SUMIF($A$3:$A$20,$A23,$J$3:$J$20) -> 0.56605771 | L23: =$B23/K23 -> 1.0062936 | M23: =SUMIF($A$3:$A$20,$A23,$M$3:$M$20) -> 0.56945505 | N23: =ABS($B23-M23) -> 0.00016520647 | O23: =SUMIF($A$3:$A$20,$A23,$M$3:$M$20) -> 0.56945505 | P23: =$B23/O23 -> 1.0002901 | Q23: =SUMIF($A$3:$A$20,$A23,$P$3:$P$20) -> 0.56961151 | R23: =ABS($B23-Q23) -> 8.742096e-06
A24: Male | B24: =Marginals!$K$10 -> 0.43037975 | C24: =SUMIF($A$3:$A$20,$A24,$D$3:$D$20) -> 0.44000034 | D24: =$B24/C24 -> 0.97813503 | E24: =SUMIF($A$3:$A$20,$A24,$G$3:$G$20) -> 0.45369227 | F24: =ABS($B24-E24) -> 0.023312519 | G24: =SUMIF($A$3:$A$20,$A24,$G$3:$G$20) -> 0.45369227 | H24: =$B24/G24 -> 0.94861601 | I24: =SUMIF($A$3:$A$20,$A24,$J$3:$J$20) -> 0.43394229 | J24: =ABS($B24-I24) -> 0.0035625412 | K24: =SUMIF($A$3:$A$20,$A24,$J$3:$J$20) -> 0.43394229 | L24: =$B24/K24 -> 0.99179029 | M24: =SUMIF($A$3:$A$20,$A24,$M$3:$M$20) -> 0.43054495 | N24: =ABS($B24-M24) -> 0.00016520647 | O24: =SUMIF($A$3:$A$20,$A24,$M$3:$M$20) -> 0.43054495 | P24: =$B24/O24 -> 0.99961629 | Q24: =SUMIF($A$3:$A$20,$A24,$P$3:$P$20) -> 0.43038849 | R24: =ABS($B24-Q24) -> 8.742096e-06
E25: Max AD | F25: =MAX(F23:F24) -> 0.023312519 | I25: Max AD | J25: =MAX(J23:J24) -> 0.0035625412 | M25: Max AD | N25: =MAX(N23:N24) -> 0.00016520647 | Q25: Max AD | R25: =MAX(R23:R24) -> 8.742096e-06
A27: AGE | B27: Start | C27: Sum(P) | D27: Factor | E27: Iteration 1 | F27: AbsDiff | G27: Sum(P) | H27: Factor | I27: Iteration 2 | J27: AbsDiff | K27: Sum(P) | L27: Factor | M27: Iteration 3 | N27: AbsDiff | O27: Sum(P) | P27: Factor | Q27: Iteration 4 | R27: AbsDiff
A28: Young | B28: =Marginals!$J$17 -> 0.25 | C28: =SUMIF($B$3:$B$20,$A28,$E$3:$E$20) -> 0.29929819 | D28: =$B28/C28 -> 0.83528738 | E28: =SUMIF($B$3:$B$20,$A28,$G$3:$G$20) -> 0.21198079 | F28: =ABS($B28-E28) -> 0.038019211 | G28: =SUMIF($B$3:$B$20,$A28,$H$3:$H$20) -> 0.21064152 | H28: =$B28/G28 -> 1.1868505 | I28: =SUMIF($B$3:$B$20,$A28,$J$3:$J$20) -> 0.24859494 | J28: =ABS($B28-I28) -> 0.0014050552 | K28: =SUMIF($B$3:$B$20,$A28,$K$3:$K$20) -> 0.24836278 | L28: =$B28/K28 -> 1.0065921 | M28: =SUMIF($B$3:$B$20,$A28,$M$3:$M$20) -> 0.24992269 | N28: =ABS($B28-M28) -> 7.7311613e-05 | O28: =SUMIF($B$3:$B$20,$A28,$N$3:$N$20) -> 0.24991187 | P28: =$B28/O28 -> 1.0003526 | Q28: =SUMIF($B$3:$B$20,$A28,$P$3:$P$20) -> 0.24999607 | R28: =ABS($B28-Q28) -> 3.9317371e-06
A29: Adult | B29: =Marginals!$K$17 -> 0.3875 | C29: =SUMIF($B$3:$B$20,$A29,$E$3:$E$20) -> 0.42057784 | D29: =$B29/C29 -> 0.92135144 | E29: =SUMIF($B$3:$B$20,$A29,$G$3:$G$20) -> 0.37725906 | F29: =ABS($B29-E29) -> 0.010240943 | G29: =SUMIF($B$3:$B$20,$A29,$H$3:$H$20) -> 0.37830463 | H29: =$B29/G29 -> 1.0243068 | I29: =SUMIF($B$3:$B$20,$A29,$J$3:$J$20) -> 0.38719523 | J29: =ABS($B29-I29) -> 0.00030477458 | K29: =SUMIF($B$3:$B$20,$A29,$K$3:$K$20) -> 0.38737319 | L29: =$B29/K29 -> 1.0003274 | M29: =SUMIF($B$3:$B$20,$A29,$M$3:$M$20) -> 0.38748429 | N29: =ABS($B29-M29) -> 1.5712209e-05 | O29: =SUMIF($B$3:$B$20,$A29,$N$3:$N$20) -> 0.38749257 | P29: =$B29/O29 -> 1.0000192 | Q29: =SUMIF($B$3:$B$20,$A29,$P$3:$P$20) -> 0.3874992 | R29: =ABS($B29-Q29) -> 8.0430375e-07
A30: Elderly | B30: =Marginals!$L$17 -> 0.3625 | C30: =SUMIF($B$3:$B$20,$A30,$E$3:$E$20) -> 0.28012397 | D30: =$B30/C30 -> 1.2940699 | E30: =SUMIF($B$3:$B$20,$A30,$G$3:$G$20) -> 0.41076015 | F30: =ABS($B30-E30) -> 0.048260154 | G30: =SUMIF($B$3:$B$20,$A30,$H$3:$H$20) -> 0.41105386 | H30: =$B30/G30 -> 0.88187958 | I30: =SUMIF($B$3:$B$20,$A30,$J$3:$J$20) -> 0.36420983 | J30: =ABS($B30-I30) -> 0.0017098297 | K30: =SUMIF($B$3:$B$20,$A30,$K$3:$K$20) -> 0.36426403 | L30: =$B30/K30 -> 0.99515727 | M30: =SUMIF($B$3:$B$20,$A30,$M$3:$M$20) -> 0.36259302 | N30: =ABS($B30-M30) -> 9.3023821e-05 | O30: =SUMIF($B$3:$B$20,$A30,$N$3:$N$20) -> 0.36259556 | P30: =$B30/O30 -> 0.99973647 | Q30: =SUMIF($B$3:$B$20,$A30,$P$3:$P$20) -> 0.36250474 | R30: =ABS($B30-Q30) -> 4.7360408e-06
E31: Max AD | F31: =MAX(F28:F30) -> 0.048260154 | I31: Max AD | J31: =MAX(J28:J30) -> 0.0017098297 | M31: Max AD | N31: =MAX(N28:N30) -> 9.3023821e-05 | Q31: Max AD | R31: =MAX(R28:R30) -> 4.7360408e-06
A33: HEALTH | B33: Start | C33: Sum(P) | D33: Factor | E33: Iteration 1 | F33: AbsDiff | G33: Sum(P) | H33: Factor | I33: Iteration 2 | J33: AbsDiff | K33: Sum(P) | L33: Factor | M33: Iteration 3 | N33: AbsDiff | O33: Sum(P) | P33: Factor | Q33: Iteration 4 | R33: AbsDiff
A34: Good | B34: =Marginals!$J$24 -> 0.20253165 | C34: =SUMIF($C$3:$C$20,$A34,$F$3:$F$20) -> 0.48702591 | D34: =$B34/C34 -> 0.41585395 | E34: =SUMIF($C$3:$C$20,$A34,$G$3:$G$20) -> 0.20253165 | F34: =ABS($B34-E34) -> 2.7755576e-17 | G34: =SUMIF($C$3:$C$20,$A34,$I$3:$I$20) -> 0.21039721 | H34: =$B34/G34 -> 0.96261564 | I34: =SUMIF($C$3:$C$20,$A34,$J$3:$J$20) -> 0.20253165 | J34: =ABS($B34-I34) -> 2.7755576e-17 | K34: =SUMIF($C$3:$C$20,$A34,$L$3:$L$20) -> 0.20297494 | L34: =$B34/K34 -> 0.99781604 | M34: =SUMIF($C$3:$C$20,$A34,$M$3:$M$20) -> 0.20253165 | N34: =ABS($B34-M34) -> 2.7755576e-17 | O34: =SUMIF($C$3:$C$20,$A34,$O$3:$O$20) -> 0.20255408 | P34: =$B34/O34 -> 0.99988923 | Q34: =SUMIF($C$3:$C$20,$A34,$P$3:$P$20) -> 0.20253165 | R34: =ABS($B34-Q34) -> 5.5511151e-17
A35: Fair | B35: =Marginals!$K$24 -> 0.37974684 | C35: =SUMIF($C$3:$C$20,$A35,$F$3:$F$20) -> 0.30279546 | D35: =$B35/C35 -> 1.2541365 | E35: =SUMIF($C$3:$C$20,$A35,$G$3:$G$20) -> 0.37974684 | F35: =ABS($B35-E35) -> 1.110223e-16 | G35: =SUMIF($C$3:$C$20,$A35,$I$3:$I$20) -> 0.381639 | H35: =$B35/G35 -> 0.99504201 | I35: =SUMIF($C$3:$C$20,$A35,$J$3:$J$20) -> 0.37974684 | J35: =ABS($B35-I35) -> 5.5511151e-17 | K35: =SUMIF($C$3:$C$20,$A35,$L$3:$L$20) -> 0.37982301 | L35: =$B35/K35 -> 0.99979945 | M35: =SUMIF($C$3:$C$20,$A35,$M$3:$M$20) -> 0.37974684 | N35: =ABS($B35-M35) -> 0 | O35: =SUMIF($C$3:$C$20,$A35,$O$3:$O$20) -> 0.37975096 | P35: =$B35/O35 -> 0.99998914 | Q35: =SUMIF($C$3:$C$20,$A35,$P$3:$P$20) -> 0.37974684 | R35: =ABS($B35-Q35) -> 0
A36: Poor | B36: =Marginals!$L$24 -> 0.41772152 | C36: =SUMIF($C$3:$C$20,$A36,$F$3:$F$20) -> 0.21017863 | D36: =$B36/C36 -> 1.9874595 | E36: =SUMIF($C$3:$C$20,$A36,$G$3:$G$20) -> 0.41772152 | F36: =ABS($B36-E36) -> 0 | G36: =SUMIF($C$3:$C$20,$A36,$I$3:$I$20) -> 0.40796379 | H36: =$B36/G36 -> 1.0239181 | I36: =SUMIF($C$3:$C$20,$A36,$J$3:$J$20) -> 0.41772152 | J36: =ABS($B36-I36) -> 1.110223e-16 | K36: =SUMIF($C$3:$C$20,$A36,$L$3:$L$20) -> 0.41720206 | L36: =$B36/K36 -> 1.0012451 | M36: =SUMIF($C$3:$C$20,$A36,$M$3:$M$20) -> 0.41772152 | N36: =ABS($B36-M36) -> 0 | O36: =SUMIF($C$3:$C$20,$A36,$O$3:$O$20) -> 0.41769496 | P36: =$B36/O36 -> 1.0000636 | Q36: =SUMIF($C$3:$C$20,$A36,$P$3:$P$20) -> 0.41772152 | R36: =ABS($B36-Q36) -> 1.110223e-16
E37: Max AD | F37: =MAX(F34:F36) -> 1.110223e-16 | I37: Max AD | J37: =MAX(J34:J36) -> 1.110223e-16 | M37: Max AD | N37: =MAX(N34:N36) -> 2.7755576e-17 | Q37: Max AD | R37: =MAX(R34:R36) -> 1.110223e-16
E39: Max AD | F39: =MAX(F25,F31,F37) -> 0.048260154 | I39: Max AD | J39: =MAX(J25,J31,J37) -> 0.0035625412 | M39: Max AD | N39: =MAX(N25,N31,N37) -> 0.00016520647 | Q39: Max AD | R39: =MAX(R25,R31,R37) -> 8.742096e-06

Sheet Local Fitting B
A1: SEED TABLE | E1: Iteration 1 | H1: Iteration 2 | K1: Iteration 3 | N1: Iteration 4
A2: Gender | B2: Age | C2: Health | D2: P(G),(A),(H) | E2: Refactored P(G) | F2: Refactored P(A) | G2: Refactored P(H) | H2: Refactored P(G) | I2: Refactored P(A) | J2: Refactored P(H) | K2: Refactored P(G) | L2: Refactored P(A) | M2: Refactored P(H) | N2: Refactored P(G) | O2: Refactored P(A) | P2: Refactored P(H)
A3: Female | B3: Young | C3: Good | D3: ='National Fitting'!P15 -> 0.096534795 | E3: =D3*$D$23 -> 0.09711756 | F3: =E3*$D$28 -> 0.11571126 | G3: =F3*$D$34 -> 0.045144572 | H3: =G3*$H$23 -> 0.047918152 | I3: =H3*$H$28 -> 0.055932254 | J3: =I3*$H$34 -> 0.053536971 | K3: =J3*$L$23 -> 0.053996622 | L3: =K3*$L$28 -> 0.054337208 | M3: =L3*$L$34 -> 0.054190661 | N3: =M3*$P$23 -> 0.054212758 | O3: =N3*$P$28 -> 0.054232082 | P3: =O3*$P$34 -> 0.054224345
A4: Female | B4: Young | C4: Fair | D4: ='National Fitting'!P16 -> 0.036698784 | E4: =D4*$D$23 -> 0.036920328 | F4: =E4*$D$28 -> 0.043988932 | G4: =F4*$D$35 -> 0.05831234 | H4: =G4*$H$23 -> 0.061894917 | I4: =H4*$H$28 -> 0.072246573 | J4: =I4*$H$35 -> 0.071844602 | K4: =J4*$L$23 -> 0.072461437 | L4: =K4*$L$28 -> 0.07291849 | M4: =L4*$L$35 -> 0.072901278 | N4: =M4*$P$23 -> 0.072931004 | O4: =N4*$P$28 -> 0.072957001 | P4: =O4*$P$35 -> 0.072956006
A5: Female | B5: Young | C5: Poor | D5: ='National Fitting'!P17 -> 0.016791724 | E5: =D5*$D$23 -> 0.016893093 | F5: =E5*$D$28 -> 0.020127371 | G5: =F5*$D$36 -> 0.041710477 | H5: =G5*$H$23 -> 0.044273073 | I5: =H5*$H$28 -> 0.051677552 | J5: =I5*$H$36 -> 0.053111621 | K5: =J5*$L$23 -> 0.053567621 | L5: =K5*$L$28 -> 0.0539055 | M5: =L5*$L$36 -> 0.05398829 | N5: =M5*$P$23 -> 0.054010304 | O5: =N5*$P$28 -> 0.054029556 | P5: =O5*$P$36 -> 0.054033989
A6: Female | B6: Adult | C6: Good | D6: ='National Fitting'!P18 -> 0.13436674 | E6: =D6*$D$23 -> 0.13517789 | F6: =E6*$D$29 -> 0.11489164 | G6: =F6*$D$34 -> 0.044824799 | H6: =G6*$H$23 -> 0.047578732 | I6: =H6*$H$29 -> 0.047362816 | J6: =I6*$H$34 -> 0.045334517 | K6: =J6*$L$23 -> 0.045723745 | L6: =K6*$L$29 -> 0.045680331 | M6: =L6*$L$34 -> 0.045557132 | N6: =M6*$P$23 -> 0.045575708 | O6: =N6*$P$29 -> 0.045573394 | P6: =O6*$P$34 -> 0.045566893
A7: Female | B7: Adult | C7: Fair | D7: ='National Fitting'!P19 -> 0.073523039 | E7: =D7*$D$23 -> 0.073966885 | F7: =E7*$D$29 -> 0.062866618 | G7: =F7*$D$35 -> 0.083336863 | H7: =G7*$H$23 -> 0.08845689 | I7: =H7*$H$29 -> 0.088055466 | J7: =I7*$H$35 -> 0.087565537 | K7: =J7*$L$23 -> 0.088317346 | L7: =K7*$L$29 -> 0.088233491 | M7: =L7*$L$35 -> 0.088212665 | N7: =M7*$P$23 -> 0.088248634 | O7: =N7*$P$29 -> 0.088244153 | P7: =O7*$P$35 -> 0.088242951
A8: Female | B8: Adult | C8: Poor | D8: ='National Fitting'!P20 -> 0.042109649 | E8: =D8*$D$23 -> 0.042363858 | F8: =E8*$D$29 -> 0.036006281 | G8: =F8*$D$36 -> 0.074616757 | H8: =G8*$H$23 -> 0.079201041 | I8: =H8*$H$29 -> 0.078841621 | J8: =I8*$H$36 -> 0.081029502 | K8: =J8*$L$23 -> 0.081725195 | L8: =K8*$L$29 -> 0.081647599 | M8: =L8*$L$36 -> 0.081772996 | N8: =M8*$P$23 -> 0.08180634 | O8: =N8*$P$29 -> 0.081802186 | P8: =O8*$P$36 -> 0.081808897
A9: Female | B9: Elderly | C9: Good | D9: ='National Fitting'!P21 -> 0.069093474 | E9: =D9*$D$23 -> 0.06951058 | F9: =E9*$D$30 -> 0.07091813 | G9: =F9*$D$34 -> 0.0276686 | H9: =G9*$H$23 -> 0.029368496 | I9: =H9*$H$30 -> 0.025028451 | J9: =I9*$H$34 -> 0.023956615 | K9: =J9*$L$23 -> 0.024162299 | L9: =K9*$L$30 -> 0.024002752 | M9: =L9*$L$34 -> 0.023938016 | N9: =M9*$P$23 -> 0.023947777 | O9: =N9*$P$30 -> 0.023938634 | P9: =O9*$P$34 -> 0.02393522
A10: Female | B10: Elderly | C10: Fair | D10: ='National Fitting'!P22 -> 0.049780244 | E10: =D10*$D$23 -> 0.050080759 | F10: =E10*$D$30 -> 0.051094866 | G10: =F10*$D$35 -> 0.067732065 | H10: =G10*$H$23 -> 0.071893369 | I10: =H10*$H$30 -> 0.061269045 | J10: =I10*$H$35 -> 0.060928152 | K10: =J10*$L$23 -> 0.061451261 | L10: =K10*$L$30 -> 0.061045489 | M10: =L10*$L$35 -> 0.06103108 | N10: =M10*$P$23 -> 0.061055966 | O10: =N10*$P$30 -> 0.061032656 | P10: =O10*$P$35 -> 0.061031824
A11: Female | B11: Elderly | C11: Poor | D11: ='National Fitting'!P23 -> 0.041101207 | E11: =D11*$D$23 -> 0.041349328 | F11: =E11*$D$30 -> 0.042186629 | G11: =F11*$D$36 -> 0.087424453 | H11: =G11*$H$23 -> 0.092795612 | I11: =H11*$H$30 -> 0.079082377 | J11: =I11*$H$36 -> 0.081276939 | K11: =J11*$L$23 -> 0.081974757 | L11: =K11*$L$30 -> 0.081433466 | M11: =L11*$L$36 -> 0.081558534 | N11: =M11*$P$23 -> 0.08159179 | O11: =N11*$P$30 -> 0.081560639 | P11: =O11*$P$36 -> 0.08156733
A12: Male | B12: Young | C12: Good | D12: ='National Fitting'!P24 -> 0.083465205 | E12: =D12*$D$24 -> 0.082823922 | F12: =E12*$D$28 -> 0.098681027 | G12: =F12*$D$34 -> 0.038500252 | H12: =G12*$H$24 -> 0.035824654 | I12: =H12*$H$28 -> 0.041816172 | J12: =I12*$H$34 -> 0.040025406 | K12: =J12*$L$24 -> 0.039590544 | L12: =K12*$L$28 -> 0.039840263 | M12: =L12*$L$34 -> 0.039732814 | N12: =M12*$P$24 -> 0.039711928 | O12: =N12*$P$28 -> 0.039726084 | P12: =O12*$P$34 -> 0.039720417
A13: Male | B13: Young | C13: Fair | D13: ='National Fitting'!P25 -> 0.043301216 | E13: =D13*$D$24 -> 0.042968523 | F13: =E13*$D$28 -> 0.051195088 | G13: =F13*$D$35 -> 0.067864921 | H13: =G13*$H$24 -> 0.063148608 | I13: =H13*$H$28 -> 0.073709938 | J13: =I13*$H$35 -> 0.073299825 | K13: =J13*$L$24 -> 0.072503448 | L13: =K13*$L$28 -> 0.072960766 | M13: =L13*$L$35 -> 0.072943545 | N13: =M13*$P$24 -> 0.072905202 | O13: =N13*$P$28 -> 0.072931189 | P13: =O13*$P$35 -> 0.072930195
A14: Male | B14: Young | C14: Poor | D14: ='National Fitting'!P26 -> 0.023208276 | E14: =D14*$D$24 -> 0.023029961 | F14: =E14*$D$28 -> 0.027439176 | G14: =F14*$D$36 -> 0.056862923 | H14: =G14*$H$24 -> 0.0529112 | I14: =H14*$H$28 -> 0.061760368 | J14: =I14*$H$36 -> 0.063474239 | K14: =J14*$L$24 -> 0.062784613 | L14: =K14*$L$28 -> 0.063180629 | M14: =L14*$L$36 -> 0.063277664 | N14: =M14*$P$24 -> 0.063244402 | O14: =N14*$P$28 -> 0.063266946 | P14: =O14*$P$36 -> 0.063272136
A15: Male | B15: Adult | C15: Good | D15: ='National Fitting'!P27 -> 0.075633258 | E15: =D15*$D$24 -> 0.075052151 | F15: =E15*$D$29 -> 0.063789017 | G15: =F15*$D$34 -> 0.024887188 | H15: =G15*$H$24 -> 0.023157638 | I15: =H15*$H$29 -> 0.023052547 | J15: =I15*$H$34 -> 0.022065328 | K15: =J15*$L$24 -> 0.021825596 | L15: =K15*$L$29 -> 0.021804873 | M15: =L15*$L$34 -> 0.021746065 | N15: =M15*$P$24 -> 0.021734635 | O15: =N15*$P$29 -> 0.021733531 | P15: =O15*$P$34 -> 0.021730431
A16: Male | B16: Adult | C16: Fair | D16: ='National Fitting'!P28 -> 0.056476961 | E16: =D16*$D$24 -> 0.056043036 | F16: =E16*$D$29 -> 0.047632614 | G16: =F16*$D$35 -> 0.063142456 | H16: =G16*$H$24 -> 0.058754333 | I16: =H16*$H$29 -> 0.058487702 | J16: =I16*$H$35 -> 0.058162284 | K16: =J16*$L$24 -> 0.057530371 | L16: =K16*$L$29 -> 0.057475748 | M16: =L16*$L$35 -> 0.057462181 | N16: =M16*$P$24 -> 0.057431976 | O16: =N16*$P$29 -> 0.05742906 | P16: =O16*$P$35 -> 0.057428277
A17: Male | B17: Adult | C17: Poor | D17: ='National Fitting'!P29 -> 0.037890351 | E17: =D17*$D$24 -> 0.037599231 | F17: =E17*$D$29 -> 0.031956686 | G17: =F17*$D$36 -> 0.066224675 | H17: =G17*$H$24 -> 0.061622352 | I17: =H17*$H$29 -> 0.061342705 | J17: =I17*$H$36 -> 0.063044986 | K17: =J17*$L$24 -> 0.062360024 | L17: =K17*$L$29 -> 0.062300815 | M17: =L17*$L$36 -> 0.062396498 | N17: =M17*$P$24 -> 0.062363699 | O17: =N17*$P$29 -> 0.062360533 | P17: =O17*$P$36 -> 0.062365649
A18: Male | B18: Elderly | C18: Good | D18: ='National Fitting'!P30 -> 0.040906526 | E18: =D18*$D$24 -> 0.040592231 | F18: =E18*$D$30 -> 0.041414201 | G18: =F18*$D$34 -> 0.016157687 | H18: =G18*$H$24 -> 0.015034799 | I18: =H18*$H$30 -> 0.012812973 | J18: =I18*$H$34 -> 0.012264261 | K18: =J18*$L$24 -> 0.012131014 | L18: =K18*$L$30 -> 0.012050911 | M18: =L18*$L$34 -> 0.01201841 | N18: =M18*$P$24 -> 0.012012093 | O18: =N18*$P$30 -> 0.012007507 | P18: =O18*$P$34 -> 0.012005794
A19: Male | B19: Elderly | C19: Fair | D19: ='National Fitting'!P31 -> 0.040219756 | E19: =D19*$D$24 -> 0.039910738 | F19: =E19*$D$30 -> 0.040718908 | G19: =F19*$D$35 -> 0.053977551 | H19: =G19*$H$24 -> 0.050226349 | I19: =H19*$H$30 -> 0.042803954 | J19: =I19*$H$35 -> 0.042565798 | K19: =J19*$L$24 -> 0.042103335 | L19: =K19*$L$30 -> 0.041825321 | M19: =L19*$L$35 -> 0.041815449 | N19: =M19*$P$24 -> 0.041793468 | O19: =N19*$P$30 -> 0.041777512 | P19: =O19*$P$35 -> 0.041776943
A20: Male | B20: Elderly | C20: Poor | D20: ='National Fitting'!P32 -> 0.038898793 | E20: =D20*$D$24 -> 0.038599925 | F20: =E20*$D$30 -> 0.039381551 | G20: =F20*$D$36 -> 0.081611419 | H20: =G20*$H$24 -> 0.075939785 | I20: =H20*$H$30 -> 0.064717486 | J20: =I20*$H$36 -> 0.066513417 | K20: =J20*$L$24 -> 0.065790772 | L20: =K20*$L$30 -> 0.065356346 | M20: =L20*$L$36 -> 0.065456722 | N20: =M20*$P$24 -> 0.065422315 | O20: =N20*$P$30 -> 0.065397338 | P20: =O20*$P$36 -> 0.065402703
A22: GENDER | B22: Start | C22: Sum(P) | D22: Factor | E22: Iteration 1 | F22: AbsDiff | G22: Sum(P) | H22: Factor | I22: Iteration 2 | J22: AbsDiff | K22: Sum(P) | L22: Factor | M22: Iteration 3 | N22: AbsDiff | O22: Sum(P) | P22: Factor | Q22: Iteration 4 | R22: AbsDiff
A23: Female | B23: =Marginals!$J$11 -> 0.56338028 | C23: =SUMIF($A$3:$A$20,$A23,$D$3:$D$20) -> 0.55999966 | D23: =$B23/C23 -> 1.0060368 | E23: =SUMIF($A$3:$A$20,$A23,$G$3:$G$20) -> 0.53077093 | F23: =ABS($B23-E23) -> 0.032609354 | G23: =SUMIF($A$3:$A$20,$A23,$G$3:$G$20) -> 0.53077093 | H23: =$B23/G23 -> 1.0614377 | I23: =SUMIF($A$3:$A$20,$A23,$J$3:$J$20) -> 0.55858446 | J23: =ABS($B23-I23) -> 0.0047958253 | K23: =SUMIF($A$3:$A$20,$A23,$J$3:$J$20) -> 0.55858446 | L23: =$B23/K23 -> 1.0085857 | M23: =SUMIF($A$3:$A$20,$A23,$M$3:$M$20) -> 0.56315065 | N23: =ABS($B23-M23) -> 0.00022963042 | O23: =SUMIF($A$3:$A$20,$A23,$M$3:$M$20) -> 0.56315065 | P23: =$B23/O23 -> 1.0004078 | Q23: =SUMIF($A$3:$A$20,$A23,$P$3:$P$20) -> 0.56336746 | R23: =ABS($B23-Q23) -> 1.2825939e-05
A24: Male | B24: =Marginals!$K$11 -> 0.43661972 | C24: =SUMIF($A$3:$A$20,$A24,$D$3:$D$20) -> 0.44000034 | D24: =$B24/C24 -> 0.99231677 | E24: =SUMIF($A$3:$A$20,$A24,$G$3:$G$20) -> 0.46922907 | F24: =ABS($B24-E24) -> 0.032609354 | G24: =SUMIF($A$3:$A$20,$A24,$G$3:$G$20) -> 0.46922907 | H24: =$B24/G24 -> 0.9305044 | I24: =SUMIF($A$3:$A$20,$A24,$J$3:$J$20) -> 0.44141554 | J24: =ABS($B24-I24) -> 0.0047958253 | K24: =SUMIF($A$3:$A$20,$A24,$J$3:$J$20) -> 0.44141554 | L24: =$B24/K24 -> 0.98913535 | M24: =SUMIF($A$3:$A$20,$A24,$M$3:$M$20) -> 0.43684935 | N24: =ABS($B24-M24) -> 0.00022963042 | O24: =SUMIF($A$3:$A$20,$A24,$M$3:$M$20) -> 0.43684935 | P24: =$B24/O24 -> 0.99947435 | Q24: =SUMIF($A$3:$A$20,$A24,$P$3:$P$20) -> 0.43663254 | R24: =ABS($B24-Q24) -> 1.2825939e-05
E25: Max AD | F25: =MAX(F23:F24) -> 0.032609354 | I25: Max AD | J25: =MAX(J23:J24) -> 0.0047958253 | M25: Max AD | N25: =MAX(N23:N24) -> 0.00022963042 | Q25: Max AD | R25: =MAX(R23:R24) -> 1.2825939e-05
A27: AGE | B27: Start | C27: Sum(P) | D27: Factor | E27: Iteration 1 | F27: AbsDiff | G27: Sum(P) | H27: Factor | I27: Iteration 2 | J27: AbsDiff | K27: Sum(P) | L27: Factor | M27: Iteration 3 | N27: AbsDiff | O27: Sum(P) | P27: Factor | Q27: Iteration 4 | R27: AbsDiff
A28: Young | B28: =Marginals!$J$18 -> 0.35714286 | C28: =SUMIF($B$3:$B$20,$A28,$E$3:$E$20) -> 0.29975339 | D28: =$B28/C28 -> 1.1914556 | E28: =SUMIF($B$3:$B$20,$A28,$G$3:$G$20) -> 0.30839549 | F28: =ABS($B28-E28) -> 0.048747371 | G28: =SUMIF($B$3:$B$20,$A28,$H$3:$H$20) -> 0.3059706 | H28: =$B28/G28 -> 1.1672456 | I28: =SUMIF($B$3:$B$20,$A28,$J$3:$J$20) -> 0.35529266 | J28: =ABS($B28-I28) -> 0.0018501924 | K28: =SUMIF($B$3:$B$20,$A28,$K$3:$K$20) -> 0.35490429 | L28: =$B28/K28 -> 1.0063075 | M28: =SUMIF($B$3:$B$20,$A28,$M$3:$M$20) -> 0.35703425 | N28: =ABS($B28-M28) -> 0.00010860529 | O28: =SUMIF($B$3:$B$20,$A28,$N$3:$N$20) -> 0.3570156 | P28: =$B28/O28 -> 1.0003565 | Q28: =SUMIF($B$3:$B$20,$A28,$P$3:$P$20) -> 0.35713709 | R28: =ABS($B28-Q28) -> 5.7683403e-06
A29: Adult | B29: =Marginals!$K$18 -> 0.35714286 | C29: =SUMIF($B$3:$B$20,$A29,$E$3:$E$20) -> 0.42020305 | D29: =$B29/C29 -> 0.84992923 | E29: =SUMIF($B$3:$B$20,$A29,$G$3:$G$20) -> 0.35703274 | F29: =ABS($B29-E29) -> 0.000110119 | G29: =SUMIF($B$3:$B$20,$A29,$H$3:$H$20) -> 0.35877099 | H29: =$B29/G29 -> 0.99546193 | I29: =SUMIF($B$3:$B$20,$A29,$J$3:$J$20) -> 0.35720215 | J29: =ABS($B29-I29) -> 5.9295839e-05 | K29: =SUMIF($B$3:$B$20,$A29,$K$3:$K$20) -> 0.35748228 | L29: =$B29/K29 -> 0.99905053 | M29: =SUMIF($B$3:$B$20,$A29,$M$3:$M$20) -> 0.35714754 | N29: =ABS($B29-M29) -> 4.6795636e-06 | O29: =SUMIF($B$3:$B$20,$A29,$N$3:$N$20) -> 0.35716099 | P29: =$B29/O29 -> 0.99994923 | Q29: =SUMIF($B$3:$B$20,$A29,$P$3:$P$20) -> 0.3571431 | R29: =ABS($B29-Q29) -> 2.4061393e-07
A30: Elderly | B30: =Marginals!$L$18 -> 0.28571429 | C30: =SUMIF($B$3:$B$20,$A30,$E$3:$E$20) -> 0.28004356 | D30: =$B30/C30 -> 1.0202494 | E30: =SUMIF($B$3:$B$20,$A30,$G$3:$G$20) -> 0.33457178 | F30: =ABS($B30-E30) -> 0.04885749 | G30: =SUMIF($B$3:$B$20,$A30,$H$3:$H$20) -> 0.33525841 | H30: =$B30/G30 -> 0.85222109 | I30: =SUMIF($B$3:$B$20,$A30,$J$3:$J$20) -> 0.28750518 | J30: =ABS($B30-I30) -> 0.0017908965 | K30: =SUMIF($B$3:$B$20,$A30,$K$3:$K$20) -> 0.28761344 | L30: =$B30/K30 -> 0.99339686 | M30: =SUMIF($B$3:$B$20,$A30,$M$3:$M$20) -> 0.28581821 | N30: =ABS($B30-M30) -> 0.00010392573 | O30: =SUMIF($B$3:$B$20,$A30,$N$3:$N$20) -> 0.28582341 | P30: =$B30/O30 -> 0.99961821 | Q30: =SUMIF($B$3:$B$20,$A30,$P$3:$P$20) -> 0.28571981 | R30: =ABS($B30-Q30) -> 5.5277264e-06
E31: Max AD | F31: =MAX(F28:F30) -> 0.04885749 | I31: Max AD | J31: =MAX(J28:J30) -> 0.0018501924 | M31: Max AD | N31: =MAX(N28:N30) -> 0.00010860529 | Q31: Max AD | R31: =MAX(R28:R30) -> 5.7683403e-06
A33: HEALTH | B33: Start | C33: Sum(P) | D33: Factor | E33: Iteration 1 | F33: AbsDiff | G33: Sum(P) | H33: Factor | I33: Iteration 2 | J33: AbsDiff | K33: Sum(P) | L33: Factor | M33: Iteration 3 | N33: AbsDiff | O33: Sum(P) | P33: Factor | Q33: Iteration 4 | R33: AbsDiff
A34: Good | B34: =Marginals!$J$25 -> 0.1971831 | C34: =SUMIF($C$3:$C$20,$A34,$F$3:$F$20) -> 0.50540528 | D34: =$B34/C34 -> 0.39014847 | E34: =SUMIF($C$3:$C$20,$A34,$G$3:$G$20) -> 0.1971831 | F34: =ABS($B34-E34) -> 2.7755576e-17 | G34: =SUMIF($C$3:$C$20,$A34,$I$3:$I$20) -> 0.20600521 | H34: =$B34/G34 -> 0.95717528 | I34: =SUMIF($C$3:$C$20,$A34,$J$3:$J$20) -> 0.1971831 | J34: =ABS($B34-I34) -> 2.7755576e-17 | K34: =SUMIF($C$3:$C$20,$A34,$L$3:$L$20) -> 0.19771634 | L34: =$B34/K34 -> 0.99730301 | M34: =SUMIF($C$3:$C$20,$A34,$M$3:$M$20) -> 0.1971831 | N34: =ABS($B34-M34) -> 0 | O34: =SUMIF($C$3:$C$20,$A34,$O$3:$O$20) -> 0.19721123 | P34: =$B34/O34 -> 0.99985735 | Q34: =SUMIF($C$3:$C$20,$A34,$P$3:$P$20) -> 0.1971831 | R34: =ABS($B34-Q34) -> 2.7755576e-17
A35: Fair | B35: =Marginals!$K$25 -> 0.3943662 | C35: =SUMIF($C$3:$C$20,$A35,$F$3:$F$20) -> 0.29749703 | D35: =$B35/C35 -> 1.3256139 | E35: =SUMIF($C$3:$C$20,$A35,$G$3:$G$20) -> 0.3943662 | F35: =ABS($B35-E35) -> 5.5511151e-17 | G35: =SUMIF($C$3:$C$20,$A35,$I$3:$I$20) -> 0.39657268 | H35: =$B35/G35 -> 0.99443613 | I35: =SUMIF($C$3:$C$20,$A35,$J$3:$J$20) -> 0.3943662 | J35: =ABS($B35-I35) -> 0 | K35: =SUMIF($C$3:$C$20,$A35,$L$3:$L$20) -> 0.39445931 | L35: =$B35/K35 -> 0.99976396 | M35: =SUMIF($C$3:$C$20,$A35,$M$3:$M$20) -> 0.3943662 | N35: =ABS($B35-M35) -> 1.110223e-16 | O35: =SUMIF($C$3:$C$20,$A35,$O$3:$O$20) -> 0.39437157 | P35: =$B35/O35 -> 0.99998637 | Q35: =SUMIF($C$3:$C$20,$A35,$P$3:$P$20) -> 0.3943662 | R35: =ABS($B35-Q35) -> 0
A36: Poor | B36: =Marginals!$L$25 -> 0.4084507 | C36: =SUMIF($C$3:$C$20,$A36,$F$3:$F$20) -> 0.19709769 | D36: =$B36/C36 -> 2.0723261 | E36: =SUMIF($C$3:$C$20,$A36,$G$3:$G$20) -> 0.4084507 | F36: =ABS($B36-E36) -> 5.5511151e-17 | G36: =SUMIF($C$3:$C$20,$A36,$I$3:$I$20) -> 0.39742211 | H36: =$B36/G36 -> 1.0277503 | I36: =SUMIF($C$3:$C$20,$A36,$J$3:$J$20) -> 0.4084507 | J36: =ABS($B36-I36) -> 5.5511151e-17 | K36: =SUMIF($C$3:$C$20,$A36,$L$3:$L$20) -> 0.40782436 | L36: =$B36/K36 -> 1.0015358 | M36: =SUMIF($C$3:$C$20,$A36,$M$3:$M$20) -> 0.4084507 | N36: =ABS($B36-M36) -> 0 | O36: =SUMIF($C$3:$C$20,$A36,$O$3:$O$20) -> 0.4084172 | P36: =$B36/O36 -> 1.000082 | Q36: =SUMIF($C$3:$C$20,$A36,$P$3:$P$20) -> 0.4084507 | R36: =ABS($B36-Q36) -> 0
E37: Max AD | F37: =MAX(F34:F36) -> 5.5511151e-17 | I37: Max AD | J37: =MAX(J34:J36) -> 5.5511151e-17 | M37: Max AD | N37: =MAX(N34:N36) -> 1.110223e-16 | Q37: Max AD | R37: =MAX(R34:R36) -> 2.7755576e-17
E39: Max AD | F39: =MAX(F25,F31,F37) -> 0.04885749 | I39: Max AD | J39: =MAX(J25,J31,J37) -> 0.0047958253 | M39: Max AD | N39: =MAX(N25,N31,N37) -> 0.00022963042 | Q39: Max AD | R39: =MAX(R25,R31,R37) -> 1.2825939e-05

Sheet Local Fitting C
A1: SEED TABLE | E1: Iteration 1 | H1: Iteration 2 | K1: Iteration 3 | N1: Iteration 4
A2: Gender | B2: Age | C2: Health | D2: P(G),(A),(H) | E2: Refactored P(G) | F2: Refactored P(A) | G2: Refactored P(H) | H2: Refactored P(G) | I2: Refactored P(A) | J2: Refactored P(H) | K2: Refactored P(G) | L2: Refactored P(A) | M2: Refactored P(H) | N2: Refactored P(G) | O2: Refactored P(A) | P2: Refactored P(H)
A3: Female | B3: Young | C3: Good | D3: ='National Fitting'!P15 -> 0.096534795 | E3: =D3*$D$23 -> 0.10055714 | F3: =E3*$D$28 -> 0.1229435 | G3: =F3*$D$34 -> 0.051937752 | H3: =G3*$H$23 -> 0.054830419 | I3: =H3*$H$28 -> 0.062868286 | J3: =I3*$H$34 -> 0.060567596 | K3: =J3*$L$23 -> 0.061027907 | L3: =K3*$L$28 -> 0.061356781 | M3: =L3*$L$34 -> 0.061217328 | N3: =M3*$P$23 -> 0.061238655 | O3: =N3*$P$28 -> 0.061257025 | P3: =O3*$P$34 -> 0.061249872
A4: Female | B4: Young | C4: Fair | D4: ='National Fitting'!P16 -> 0.036698784 | E4: =D4*$D$23 -> 0.038227923 | F4: =E4*$D$28 -> 0.046738349 | G4: =F4*$D$35 -> 0.062814566 | H4: =G4*$H$23 -> 0.066313015 | I4: =H4*$H$28 -> 0.076034173 | J4: =I4*$H$35 -> 0.075762604 | K4: =J4*$L$23 -> 0.076338397 | L4: =K4*$L$28 -> 0.076749778 | M4: =L4*$L$35 -> 0.076740586 | N4: =M4*$P$23 -> 0.076767321 | O4: =N4*$P$28 -> 0.07679035 | P4: =O4*$P$35 -> 0.076789797
A5: Female | B5: Young | C5: Poor | D5: ='National Fitting'!P17 -> 0.016791724 | E5: =D5*$D$23 -> 0.01749139 | F5: =E5*$D$28 -> 0.021385381 | G5: =F5*$D$36 -> 0.043209982 | H5: =G5*$H$23 -> 0.045616557 | I5: =H5*$H$28 -> 0.052303717 | J5: =I5*$H$36 -> 0.053648322 | K5: =J5*$L$23 -> 0.054056047 | L5: =K5*$L$28 -> 0.054347351 | M5: =L5*$L$36 -> 0.054423811 | N5: =M5*$P$23 -> 0.054442771 | O5: =N5*$P$28 -> 0.054459103 | P5: =O5*$P$36 -> 0.054463085
A6: Female | B6: Adult | C6: Good | D6: ='National Fitting'!P18 -> 0.13436674 | E6: =D6*$D$23 -> 0.13996544 | F6: =E6*$D$29 -> 0.13285709 | G6: =F6*$D$34 -> 0.05612577 | H6: =G6*$H$23 -> 0.059251688 | I6: =H6*$H$29 -> 0.058437606 | J6: =I6*$H$34 -> 0.056299059 | K6: =J6*$L$23 -> 0.056726929 | L6: =K6*$L$29 -> 0.056660169 | M6: =L6*$L$34 -> 0.05653139 | N6: =M6*$P$23 -> 0.056551085 | O6: =N6*$P$29 -> 0.056547535 | P6: =O6*$P$34 -> 0.056540932
A7: Female | B7: Adult | C7: Fair | D7: ='National Fitting'!P19 -> 0.073523039 | E7: =D7*$D$23 -> 0.076586546 | F7: =E7*$D$29 -> 0.072696985 | G7: =F7*$D$35 -> 0.097701987 | H7: =G7*$H$23 -> 0.10314349 | I7: =H7*$H$29 -> 0.10172636 | J7: =I7*$H$35 -> 0.10136303 | K7: =J7*$L$23 -> 0.10213338 | L7: =K7*$L$29 -> 0.10201318 | M7: =L7*$L$35 -> 0.10200097 | N7: =M7*$P$23 -> 0.1020365 | O7: =N7*$P$29 -> 0.1020301 | P7: =O7*$P$35 -> 0.10202936
A8: Female | B8: Adult | C8: Poor | D8: ='National Fitting'!P20 -> 0.042109649 | E8: =D8*$D$23 -> 0.043864244 | F8: =E8*$D$29 -> 0.041636534 | G8: =F8*$D$36 -> 0.084128212 | H8: =G8*$H$23 -> 0.088813723 | I8: =H8*$H$29 -> 0.087593477 | J8: =I8*$H$36 -> 0.089845299 | K8: =J8*$L$23 -> 0.090528119 | L8: =K8*$L$29 -> 0.090421579 | M8: =L8*$L$36 -> 0.090548792 | N8: =M8*$P$23 -> 0.090580337 | O8: =N8*$P$29 -> 0.090574652 | P8: =O8*$P$36 -> 0.090581275
A9: Female | B9: Elderly | C9: Good | D9: ='National Fitting'!P21 -> 0.069093474 | E9: =D9*$D$23 -> 0.071972413 | F9: =E9*$D$30 -> 0.060416143 | G9: =F9*$D$34 -> 0.025522933 | H9: =G9*$H$23 -> 0.026944429 | I9: =H9*$H$30 -> 0.022941406 | J9: =I9*$H$34 -> 0.022101857 | K9: =J9*$L$23 -> 0.02226983 | L9: =K9*$L$30 -> 0.022130298 | M9: =L9*$L$34 -> 0.02208 | N9: =M9*$P$23 -> 0.022087692 | O9: =N9*$P$30 -> 0.022079785 | P9: =O9*$P$34 -> 0.022077207
A10: Female | B10: Elderly | C10: Fair | D10: ='National Fitting'!P22 -> 0.049780244 | E10: =D10*$D$23 -> 0.051854453 | F10: =E10*$D$30 -> 0.043528429 | G10: =F10*$D$35 -> 0.058500555 | H10: =G10*$H$23 -> 0.061758736 | I10: =H10*$H$30 -> 0.052583495 | J10: =I10*$H$35 -> 0.052395684 | K10: =J10*$L$23 -> 0.052793889 | L10: =K10*$L$30 -> 0.052463109 | M10: =L10*$L$35 -> 0.052456826 | N10: =M10*$P$23 -> 0.052475101 | O10: =N10*$P$30 -> 0.052456315 | P10: =O10*$P$35 -> 0.052455938
A11: Female | B11: Elderly | C11: Poor | D11: ='National Fitting'!P23 -> 0.041101207 | E11: =D11*$D$23 -> 0.042813783 | F11: =E11*$D$30 -> 0.035939377 | G11: =F11*$D$36 -> 0.072616888 | H11: =G11*$H$23 -> 0.076661277 | I11: =H11*$H$30 -> 0.065272026 | J11: =I11*$H$36 -> 0.066950016 | K11: =J11*$L$23 -> 0.067458834 | L11: =K11*$L$30 -> 0.06703617 | M11: =L11*$L$36 -> 0.067130482 | N11: =M11*$P$23 -> 0.067153869 | O11: =N11*$P$30 -> 0.067129829 | P11: =O11*$P$36 -> 0.067134738
A12: Male | B12: Young | C12: Good | D12: ='National Fitting'!P24 -> 0.083465205 | E12: =D12*$D$24 -> 0.079038958 | F12: =E12*$D$28 -> 0.096634871 | G12: =F12*$D$34 -> 0.040823614 | H12: =G12*$H$24 -> 0.038015796 | I12: =H12*$H$28 -> 0.043588722 | J12: =I12*$H$34 -> 0.041993575 | K12: =J12*$L$24 -> 0.04155477 | L12: =K12*$L$28 -> 0.041778705 | M12: =L12*$L$34 -> 0.041683749 | N12: =M12*$P$24 -> 0.041663435 | O12: =N12*$P$28 -> 0.041675933 | P12: =O12*$P$34 -> 0.041671066
A13: Male | B13: Young | C13: Fair | D13: ='National Fitting'!P25 -> 0.043301216 | E13: =D13*$D$24 -> 0.041004908 | F13: =E13*$D$28 -> 0.050133556 | G13: =F13*$D$35 -> 0.067377594 | H13: =G13*$H$24 -> 0.062743413 | I13: =H13*$H$28 -> 0.071941284 | J13: =I13*$H$35 -> 0.071684334 | K13: =J13*$L$24 -> 0.07093528 | L13: =K13*$L$28 -> 0.071317544 | M13: =L13*$L$35 -> 0.071309002 | N13: =M13*$P$24 -> 0.071274251 | O13: =N13*$P$28 -> 0.071295631 | P13: =O13*$P$35 -> 0.071295118
A14: Male | B14: Young | C14: Poor | D14: ='National Fitting'!P26 -> 0.023208276 | E14: =D14*$D$24 -> 0.021977517 | F14: =E14*$D$28 -> 0.026870224 | G14: =F14*$D$36 -> 0.054292317 | H14: =G14*$H$24 -> 0.050558131 | I14: =H14*$H$28 -> 0.057969701 | J14: =I14*$H$36 -> 0.059459965 | K14: =J14*$L$24 -> 0.058838647 | L14: =K14*$L$28 -> 0.059155724 | M14: =L14*$L$36 -> 0.059238949 | N14: =M14*$P$24 -> 0.05921008 | O14: =N14*$P$28 -> 0.059227841 | P14: =O14*$P$36 -> 0.059232172
A15: Male | B15: Adult | C15: Good | D15: ='National Fitting'!P27 -> 0.075633258 | E15: =D15*$D$24 -> 0.071622348 | F15: =E15*$D$29 -> 0.067984902 | G15: =F15*$D$34 -> 0.028720371 | H15: =G15*$H$24 -> 0.026745005 | I15: =H15*$H$29 -> 0.026377545 | J15: =I15*$H$34 -> 0.025412248 | K15: =J15*$L$24 -> 0.025146707 | L15: =K15*$L$29 -> 0.025117113 | M15: =L15*$L$34 -> 0.025060026 | N15: =M15*$P$24 -> 0.025047813 | O15: =N15*$P$29 -> 0.025046241 | P15: =O15*$P$34 -> 0.025043316
